{"name": "Тест на создание фейковых данных", "status": "broken", "statusDetails": {"message": "AttributeError: 'Database' object has no attribute 'test_create_fake_data'. Did you mean: 'test_create_fake_users'?", "trace": "@allure.title(\"Тест на создание фейковых данных\")\n    def test_create_fake_data():\n>       db.test_create_fake_data(2, 2, 2, 2, 2)\nE       AttributeError: 'Database' object has no attribute 'test_create_fake_data'. Did you mean: 'test_create_fake_users'?\n\napi_test.py:15: AttributeError"}, "start": 1703592033929, "stop": 1703592033929, "uuid": "0f69ca7a-781c-4938-95bc-dac1ca9340dc", "historyId": "b355e833ec90965f54a795af8b707372", "testCaseId": "b355e833ec90965f54a795af8b707372", "fullName": "api_test#test_create_fake_data", "labels": [{"name": "suite", "value": "api_test"}, {"name": "host", "value": "DESKTOP-TV6CGIP"}, {"name": "thread", "value": "2428-MainThread"}, {"name": "framework", "value": "pytest"}, {"name": "language", "value": "cpython3"}, {"name": "package", "value": "api_test"}]}